Workbook

Sheet Margin Borrow Rates
A1: Date | B1: Binance | C1: OKX | D1: Bybit | E1: KuCoin | F1: Gate I.O | G1: BTC Price $
A2: 46023 | B2: 0.0436 | C2: 0.0316 | D2: 0.0385 | E2: 0.0454 | F2: 0.0443 | G2: 88728
A3: 46024 | B3: 0.0446 | C3: 0.0316 | D3: 0.0394 | E3: 0.0462 | F3: 0.0436 | G3: 89926
A4: 46025 | B4: 0.0459 | C4: 0.0316 | D4: 0.0397 | E4: 0.0472 | F4: 0.0427 | G4: 90594
A5: 46026 | B5: 0.0459 | C5: 0.0316 | D5: 0.0396 | E5: 0.0478 | F5: 0.0404 | G5: 91373
A6: 46027 | B6: 0.0462 | C6: 0.0316 | D6: 0.0395 | E6: 0.0479 | F6: 0.0489 | G6: 93927
A7: 46028 | B7: 0.0458 | C7: 0.0316 | D7: 0.0397 | E7: 0.047 | F7: 0.0503 | G7: 93667
A8: 46029 | B8: 0.0456 | C8: 0.0316 | D8: 0.0398 | E8: 0.0475 | F8: 0.0514 | G8: 91257
A9: 46030 | B9: 0.0461 | C9: 0.0316 | D9: 0.0384 | E9: 0.048 | F9: 0.0506 | G9: 90984
A10: 46031 | B10: 0.0461 | C10: 0.0316 | D10: 0.0373 | E10: 0.0486 | F10: 0.0517 | G10: 90505
A11: 46032 | B11: 0.0465 | C11: 0.0316 | D11: 0.0371 | E11: 0.0475 | F11: 0.0518 | G11: 90442
A12: 46033 | B12: 0.0466 | C12: 0.0316 | D12: 0.0373 | E12: 0.0481 | F12: 0.0521 | G12: 90819
A13: 46034 | B13: 0.0471 | C13: 0.0316 | D13: 0.0383 | E13: 0.0489 | F13: 0.0522 | G13: 91135
... A224: 46245 | B224: 0.0407 | C224: 0.0276 | D224: 0.0447 | E224: 0.0428 | F224: 0.0515 | G224: 63971
A225: 46246 | B225: 0.0407 | C225: 0.0276 | D225: 0.044 | E225: 0.0421 | F225: 0.0517
A226: 46247
A227: 46248
A228: 46249
A229: 46250

Sheet Daily Data
A1: Binance | S1: OKX | AK1: ByBit | BC1: Gate I.O
A2: Earn | B2: 7D | C2: 14D | D2: 30D | E2: 60D | F2: 90D | G2: 180D | H2: Flexible | I2: Borrow | J2: 7D | K2: 14D | L2: 30D | M2: 60D | N2: 90D | O2: 180D | P2: Flexible | Q2: Spread | S2: Earn | T2: 7D | U2: 14D | V2: 30D | W2: 60D | X2: 90D | Y2: 180D | Z2: Flexible | AA2: Borrow | AB2: 7D | AC2: 14D | AD2: 30D | AE2: 60D | AF2: 90D | AG2: 180D | AH2: Flexible | AI2: Spread | AK2: Earn | AL2: 7D | AM2: 14D | AN2: 30D | AO2: 60D | AP2: 90D | AQ2: 180D | AR2: Flexible | AS2: Borrow | AT2: 7D | AU2: 14D | AV2: 30D | AW2: 60D | AX2: 90D | AY2: 180D | AZ2: Flexible | BA2: Spread | BC2: Earn | BD2: 7D | BE2: 14D | BF2: 30D | BG2: 60D | BH2: 90D | BI2: 180D | BJ2: Flexible | BK2: Borrow | BL2: 7D | BM2: 14D | BN2: 30D | BO2: 60D | BP2: 90D | BQ2: 180D | BR2: Flexible | BS2: Spread
AL3: Sınırlı | AP3: VIP | AQ3: VIP
A4: 46077 | B4: N/A | C4: N/A | D4: P2P | E4: N/A | F4: P2P | G4: N/A | H4: 0.0084 | I4: 46077 | J4: N/A | K4: N/A | L4: P2P | M4: N/A | N4: P2P | O4: P2P | P4: 0.0305 | Q4: =P4-H4 -> 0.0221 | S4: 46077 | T4: N/A | U4: N/A | V4: N/A | W4: N/A | X4: 0.035 | Y4: N/A | Z4: 0.0113 | AA4: 46077 | AB4: N/A | AC4: N/A | AD4: N/A | AE4: N/A | AF4: N/A | AG4: N/A | AH4: 0.0297 | AI4: =AH4-Z4 -> 0.0184 | AK4: 46077 | AL4: 0.02 | AP4: 0.025 | AQ4: 0.027 | AR4: 0.006 | AS4: 46077 | AT4: 0.032 | AU4: 0.032 | AV4: 0.045 | AW4: 0.051 | AX4: 0.0588 | AY4: 0.05 | AZ4: 0.0349 | BA4: =AZ4-AR4 -> 0.0289 | BC4: 46077 | BD4: 0.0088 | BE4: 0.0089 | BF4: 0.0092 | BJ4: 0.0076 | BK4: 46077 | BL4: 0.04 | BN4: 0.0548 | BR4: 0.0307 | BS4: =BR4-BJ4 -> 0.0231
A5: 46078 | B5: N/A | C5: N/A | D5: P2P | E5: N/A | F5: P2P | G5: N/A | H5: 0.0085 | I5: 46078 | J5: N/A | K5: N/A | L5: P2P | M5: N/A | N5: P2P | O5: P2P | P5: 0.0304 | Q5: =P5-H5 -> 0.0219 | S5: 46078 | T5: N/A | U5: N/A | V5: N/A | W5: N/A | X5: 0.035 | Y5: N/A | Z5: 0.0113 | AA5: 46078 | AB5: N/A | AC5: N/A | AD5: N/A | AE5: N/A | AF5: N/A | AG5: N/A | AH5: 0.03 | AI5: =AH5-Z5 -> 0.0187 | AK5: 46078 | AL5: 0.02 | AP5: 0.025 | AQ5: 0.027 | AR5: 0.006 | AS5: 46078 | AT5: 0.03 | AU5: 0.0315 | AV5: 0.0439 | AW5: 0.0499 | AX5: 0.0585 | AY5: 0.0645 | AZ5: 0.0344 | BA5: =AZ5-AR5 -> 0.0284 | BC5: 46078 | BD5: 0.0088 | BE5: 0.0089 | BF5: 0.0092 | BJ5: 0.0076 | BK5: 46078 | BL5: 0.04 | BN5: 0.0548 | BR5: 0.0307 | BS5: =BR5-BJ5 -> 0.0231
A6: 46079 | B6: N/A | C6: N/A | D6: P2P | E6: N/A | F6: P2P | G6: N/A | H6: 0.0088 | I6: 46079 | J6: N/A | K6: N/A | L6: P2P | M6: N/A | N6: P2P | O6: P2P | P6: 0.0319 | Q6: =P6-H6 -> 0.0231 | S6: 46079 | T6: N/A | U6: N/A | V6: N/A | W6: N/A | X6: 0.03 | Y6: N/A | Z6: 0.0114 | AA6: 46079 | AB6: N/A | AC6: N/A | AD6: N/A | AE6: N/A | AF6: N/A | AG6: N/A | AH6: 0.025 | AI6: =AH6-Z6 -> 0.0136 | AK6: 46079 | AL6: 0.02 | AP6: 0.025 | AQ6: 0.027 | AR6: 0.0061 | AS6: 46079 | AT6: 0.033 | AU6: 0.034 | AV6: 0.043 | AW6: 0.05 | AX6: 0.0585 | AY6: 0.0654 | AZ6: 0.035 | BA6: =AZ6-AR6 -> 0.0289 | BC6: 46079 | BD6: 0.0086 | BE6: 0.0088 | BF6: 0.009 | BJ6: 0.0076 | BK6: 46079 | BL6: 0.0398 | BN6: 0.0548 | BR6: 0.0307 | BS6: =BR6-BJ6 -> 0.0231
A7: 46080 | B7: N/A | C7: N/A | D7: P2P | E7: N/A | F7: P2P | G7: N/A | H7: 0.0092 | I7: 46080 | J7: N/A | K7: N/A | L7: P2P | M7: N/A | N7: P2P | O7: P2P | P7: 0.0322 | Q7: =P7-H7 -> 0.023 | S7: 46080 | T7: N/A | U7: N/A | V7: N/A | W7: N/A | X7: 0.03 | Y7: N/A | Z7: 0.0114 | AA7: 46080 | AB7: N/A | AC7: N/A | AD7: N/A | AE7: N/A | AF7: N/A | AG7: N/A | AH7: 0.025 | AI7: =AH7-Z7 -> 0.0136 | AK7: 46080 | AL7: 0.02 | AP7: 0.025 | AQ7: 0.0275 | AR7: 0.0061 | AS7: 46080 | AT7: 0.03 | AU7: 0.034 | AV7: 0.0434 | AW7: 0.05 | AX7: 0.0547 | AY7: 0.0647 | AZ7: 0.0354 | BA7: =AZ7-AR7 -> 0.0293 | BC7: 46080 | BD7: 0.0084 | BE7: 0.0086 | BF7: 0.0089 | BJ7: 0.0074 | BK7: 46080 | BL7: 0.04 | BN7: 0.0548 | BR7: 0.0304 | BS7: =BR7-BJ7 -> 0.023
A8: 46081 | B8: N/A | C8: N/A | D8: P2P | E8: N/A | F8: P2P | G8: N/A | H8: 0.0086 | I8: 46081 | J8: N/A | K8: N/A | L8: P2P | M8: N/A | N8: P2P | O8: P2P | P8: 0.0313 | Q8: =P8-H8 -> 0.0227 | S8: 46081 | T8: N/A | U8: N/A | V8: N/A | W8: N/A | X8: 0.03 | Y8: N/A | Z8: 0.011 | AA8: 46081 | AB8: N/A | AC8: N/A | AD8: N/A | AE8: N/A | AF8: N/A | AG8: N/A | AH8: 0.025 | AI8: =AH8-Z8 -> 0.014 | AK8: 46081 | AL8: 0.02 | AP8: 0.026 | AQ8: 0.0285 | AR8: 0.006 | AS8: 46081 | AT8: 0.0311 | AU8: 0.0335 | AV8: 0.032 | AW8: 0.05 | AX8: 0.0547 | AY8: 0.065 | AZ8: 0.0351 | BA8: =AZ8-AR8 -> 0.0291 | BC8: 46081 | BD8: 0.0083 | BE8: 0.0084 | BF8: 0.0086 | BJ8: 0.0073 | BK8: 46081 | BL8: 0.0398 | BN8: 0.0548 | BR8: 0.0302 | BS8: =BR8-BJ8 -> 0.0229
A9: 46082 | B9: N/A | C9: N/A | D9: P2P | E9: N/A | F9: P2P | G9: N/A | H9: 0.0085 | I9: 46082 | J9: N/A | K9: N/A | L9: P2P | M9: N/A | N9: P2P | O9: P2P | P9: 0.0311 | Q9: =P9-H9 -> 0.0226 | S9: 46082 | T9: N/A | U9: N/A | V9: N/A | W9: N/A | X9: 0.03 | Y9: N/A | Z9: 0.011 | AA9: 46082 | AB9: N/A | AC9: N/A | AD9: N/A | AE9: N/A | AF9: N/A | AG9: N/A | AH9: 0.025 | AI9: =AH9-Z9 -> 0.014 | AK9: 46082 | AL9: 0.02 | AP9: 0.026 | AQ9: 0.0285 | AR9: 0.006 | AS9: 46082 | AT9: 0.032 | AU9: 0.0335 | AV9: 0.032 | AW9: 0.05 | AX9: 0.0537 | AY9: 0.0651 | AZ9: 0.0351 | BA9: =AZ9-AR9 -> 0.0291 | BC9: 46082 | BD9: 0.0079 | BE9: 0.0081 | BF9: 0.0083 | BJ9: 0.0071 | BK9: 46082 | BL9: 0.0396 | BN9: 0.0548 | BR9: 0.0298 | BS9: =BR9-BJ9 -> 0.0227
A10: 46083 | B10: N/A | C10: N/A | D10: P2P | E10: N/A | F10: P2P | G10: N/A | H10: 0.0086 | I10: 46083 | J10: N/A | K10: N/A | L10: P2P | M10: N/A | N10: P2P | O10: P2P | P10: 0.0313 | Q10: =P10-H10 -> 0.0227 | S10: 46083 | T10: N/A | U10: N/A | V10: N/A | W10: N/A | X10: 0.03 | Y10: N/A | Z10: 0.0111 | AA10: 46083 | AB10: N/A | AC10: N/A | AD10: N/A | AE10: N/A | AF10: N/A | AG10: N/A | AH10: 0.025 | AI10: =AH10-Z10 -> 0.0139 | AK10: 46083 | AL10: 0.02 | AP10: 0.026 | AQ10: 0.0285 | AR10: 0.006 | AS10: 46083 | AT10: 0.033 | AU10: 0.033 | AV10: 0.043 | AW10: 0.0499 | AX10: 0.0549 | AY10: 0.065 | AZ10: 0.0347 | BA10: =AZ10-AR10 -> 0.0287 | BC10: 46083 | BD10: 0.0078 | BE10: 0.008 | BF10: 0.0082 | BJ10: 0.0069 | BK10: 46083 | BL10: 0.0386 | BN10: 0.0548 | BR10: 0.0294 | BS10: =BR10-BJ10 -> 0.0225
A11: 46084 | B11: N/A | C11: N/A | D11: P2P | E11: N/A | F11: P2P | G11: N/A | H11: 0.0086 | I11: 46084 | J11: N/A | K11: N/A | L11: P2P | M11: N/A | N11: P2P | O11: P2P | P11: 0.0312 | Q11: =P11-H11 -> 0.0226 | S11: 46084 | T11: N/A | U11: N/A | V11: N/A | W11: N/A | X11: 0.03 | Y11: N/A | Z11: 0.0112 | AA11: 46084 | AB11: N/A | AC11: N/A | AD11: N/A | AE11: N/A | AF11: N/A | AG11: N/A | AH11: 0.025 | AI11: =AH11-Z11 -> 0.0138 | AK11: 46084 | AL11: 0.02 | AP11: 0.026 | AQ11: 0.0285 | AR11: 0.0067 | AS11: 46084 | AT11: 0.046 | AU11: 0.032 | AV11: 0.042 | AW11: 0.059 | AX11: 0.0585 | AY11: 0.0654 | AZ11: 0.0351 | BA11: =AZ11-AR11 -> 0.0284 | BC11: 46084 | BD11: 0.0077 | BE11: 0.0079 | BF11: 0.0081 | BJ11: 0.0076 | BK11: 46084 | BL11: 0.0386 | BN11: 0.0548 | BR11: 0.0308 | BS11: =BR11-BJ11 -> 0.0232
A12: 46085 | B12: N/A | C12: N/A | D12: P2P | E12: N/A | F12: P2P | G12: N/A | H12: 0.0082 | I12: 46085 | J12: N/A | K12: N/A | L12: P2P | M12: N/A | N12: P2P | O12: P2P | P12: 0.0304 | Q12: =P12-H12 -> 0.0222 | S12: 46085 | T12: N/A | U12: N/A | V12: N/A | W12: N/A | X12: 0.03 | Y12: N/A | Z12: 0.0113 | AA12: 46085 | AB12: N/A | AC12: N/A | AD12: N/A | AE12: N/A | AF12: N/A | AG12: N/A | AH12: 0.025 | AI12: =AH12-Z12 -> 0.0137 | AK12: 46085 | AL12: 0.02 | AP12: 0.027 | AQ12: 0.028 | AR12: 0.0073 | AS12: 46085 | AT12: 0.046 | AU12: 0.04 | AV12: 0.042 | AW12: 0.0575 | AX12: 0.058 | AY12: 0.07 | AZ12: 0.0346 | BA12: =AZ12-AR12 -> 0.0273 | BC12: 46085 | BD12: 0.0077 | BE12: 0.0078 | BF12: 0.008 | BJ12: 0.0074 | BK12: 46085 | BL12: 0.0386 | BN12: 0.0548 | BR12: 0.0304 | BS12: =BR12-BJ12 -> 0.023
A13: 46086 | B13: N/A | C13: N/A | D13: P2P | E13: N/A | F13: P2P | G13: N/A | H13: 0.0089 | I13: 46086 | J13: N/A | K13: N/A | L13: P2P | M13: N/A | N13: P2P | O13: P2P | P13: 0.0317 | Q13: =P13-H13 -> 0.0228 | S13: 46086 | T13: N/A | U13: N/A | V13: N/A | W13: N/A | X13: 0.03 | Y13: N/A | Z13: 0.0117 | AA13: 46086 | AB13: N/A | AC13: N/A | AD13: N/A | AE13: N/A | AF13: N/A | AG13: N/A | AH13: 0.025 | AI13: =AH13-Z13 -> 0.0133 | AK13: 46086 | AL13: 0.02 | AP13: 0.028 | AQ13: 0.029 | AR13: 0.0075 | AS13: 46086 | AT13: 0.036 | AU13: 0.04 | AV13: 0.042 | AW13: 0.0573 | AX13: 0.0579 | AY13: 0.066 | AZ13: 0.0356 | BA13: =AZ13-AR13 -> 0.0281 | BC13: 46086 | BD13: 0.0076 | BE13: 0.0078 | BF13: 0.008 | BJ13: 0.0075 | BK13: 46086 | BL13: 0.0386 | BN13: 0.0548 | BR13: 0.0322 | BS13: =BR13-BJ13 -> 0.0247
A14: 46087 | B14: N/A | C14: N/A | D14: P2P | E14: N/A | F14: P2P | G14: N/A | H14: 0.0089 | I14: 46087 | J14: N/A | K14: N/A | L14: P2P | M14: N/A | N14: P2P | O14: P2P | P14: 0.0323 | Q14: =P14-H14 -> 0.0234 | S14: 46087 | T14: N/A | U14: N/A | V14: N/A | W14: N/A | X14: 0.03 | Y14: N/A | Z14: 0.0117 | AA14: 46087 | AB14: N/A | AC14: N/A | AD14: N/A | AE14: N/A | AF14: N/A | AG14: N/A | AH14: 0.025 | AI14: =AH14-Z14 -> 0.0133 | AK14: 46087 | AL14: 0.02 | AP14: N/A | AQ14: 0.0266 | AR14: 0.0073 | AS14: 46087 | AT14: 0.039 | AU14: 0.0345 | AV14: 0.04 | AW14: 0.0572 | AX14: 0.0579 | AY14: 0.0685 | AZ14: 0.0356 | BA14: =AZ14-AR14 -> 0.0283 | BC14: 46087 | BD14: 0.0076 | BE14: 0.0078 | BF14: 0.008 | BJ14: 0.0078 | BK14: 46087 | BL14: 0.039 | BN14: 0.0548 | BR14: 0.0326 | BS14: =BR14-BJ14 -> 0.0248
A15: 46088 | B15: N/A | C15: N/A | D15: P2P | E15: N/A | F15: P2P | G15: N/A | H15: 0.0082 | I15: 46088 | J15: N/A | K15: N/A | L15: P2P | M15: N/A | N15: P2P | O15: P2P | P15: 0.0318 | Q15: =P15-H15 -> 0.0236 | S15: 46088 | T15: N/A | U15: N/A | V15: N/A | W15: N/A | X15: 0.03 | Y15: N/A | Z15: 0.0117 | AA15: 46088 | AB15: N/A | AC15: N/A | AD15: N/A | AE15: N/A | AF15: N/A | AG15: N/A | AH15: 0.025 | AI15: =AH15-Z15 -> 0.0133 | AK15: 46088 | AL15: 0.02 | AP15: N/A | AQ15: 0.0266 | AR15: 0.0069 | AS15: 46088 | AT15: 0.0363 | AU15: 0.04 | AV15: 0.042 | AW15: 0.0573 | AX15: 0.058 | AY15: 0.0685 | AZ15: 0.0356 | BA15: =AZ15-AR15 -> 0.0287 | BC15: 46088 | BD15: 0.0077 | BE15: 0.0079 | BF15: 0.0082 | BJ15: 0.0076 | BK15: 46088 | BL15: 0.0386 | BN15: 0.0548 | BR15: 0.0323 | BS15: =BR15-BJ15 -> 0.0247
A16: 46089 | B16: N/A | C16: N/A | D16: P2P | E16: N/A | F16: P2P | G16: N/A | H16: 0.008 | I16: 46089 | J16: N/A | K16: N/A | L16: P2P | M16: N/A | N16: P2P | O16: P2P | P16: 0.0307 | Q16: =P16-H16 -> 0.0227 | S16: 46089 | T16: N/A | U16: N/A | V16: N/A | W16: N/A | X16: 0.03 | Y16: N/A | Z16: 0.0117 | AA16: 46089 | AB16: N/A | AC16: N/A | AD16: N/A | AE16: N/A | AF16: N/A | AG16: N/A | AH16: 0.025 | AI16: =AH16-Z16 -> 0.0133 | AK16: 46089 | AL16: 0.02 | AP16: N/A | AQ16: 0.0265 | AR16: 0.0066 | AS16: 46089 | AT16: 0.0375 | AU16: 0.0409 | AV16: 0.042 | AW16: 0.0573 | AX16: 0.058 | AY16: 0.0685 | AZ16: 0.0354 | BA16: =AZ16-AR16 -> 0.0288 | BC16: 46089 | BD16: 0.0076 | BE16: 0.0078 | BF16: 0.0081 | BJ16: 0.0075 | BK16: 46089 | BL16: 0.0386 | BN16: 0.0548 | BR16: 0.0323 | BS16: =BR16-BJ16 -> 0.0248
A17: 46090 | B17: N/A | C17: N/A | D17: P2P | E17: N/A | F17: P2P | G17: N/A | H17: 0.0081 | I17: 46090 | J17: N/A | K17: N/A | L17: P2P | M17: N/A | N17: P2P | O17: P2P | P17: 0.031 | Q17: =P17-H17 -> 0.0229 | S17: 46090 | T17: N/A | U17: N/A | V17: N/A | W17: N/A | X17: 0.03 | Y17: N/A | Z17: 0.0117 | AA17: 46090 | AB17: N/A | AC17: N/A | AD17: N/A | AE17: N/A | AF17: N/A | AG17: N/A | AH17: 0.025 | AI17: =AH17-Z17 -> 0.0133 | AK17: 46090 | AL17: 0.02 | AP17: N/A | AQ17: 0.0265 | AR17: 0.0064 | AS17: 46090 | AT17: 0.032 | AU17: 0.0409 | AV17: 0.038 | AW17: 0.05 | AX17: 0.0524 | AY17: 0.0659 | AZ17: 0.0344 | BA17: =AZ17-AR17 -> 0.028 | BC17: 46090 | BD17: 0.0078 | BE17: 0.0079 | BF17: 0.0081 | BJ17: 0.0071 | BK17: 46090 | BL17: 0.0386 | BN17: 0.0548 | BR17: 0.0314 | BS17: =BR17-BJ17 -> 0.0243
A18: 46091 | B18: N/A | C18: N/A | D18: P2P | E18: N/A | F18: P2P | G18: N/A | H18: 0.0081 | I18: 46091 | J18: N/A | K18: N/A | L18: P2P | M18: N/A | N18: P2P | O18: P2P | P18: 0.0302 | Q18: =P18-H18 -> 0.0221 | S18: 46091 | T18: N/A | U18: N/A | V18: N/A | W18: N/A | X18: 0.03 | Y18: N/A | Z18: 0.0115 | AA18: 46091 | AB18: N/A | AC18: N/A | AD18: N/A | AE18: N/A | AF18: N/A | AG18: N/A | AH18: 0.025 | AI18: =AH18-Z18 -> 0.0135 | AK18: 46091 | AL18: 0.02 | AP18: N/A | AQ18: 0.0265 | AR18: 0.0066 | AS18: 46091 | AT18: 0.032 | AU18: 0.035 | AV18: 0.038 | AW18: 0.05 | AX18: 0.0585 | AY18: 0.061 | AZ18: 0.0341 | BA18: =AZ18-AR18 -> 0.0275 | BC18: 46091 | BD18: 0.0078 | BE18: 0.0079 | BF18: 0.0082 | BJ18: 0.0074 | BK18: 46091 | BL18: 0.0386 | BN18: 0.0548 | BR18: 0.032 | BS18: =BR18-BJ18 -> 0.0246
A19: 46092 | B19: N/A | C19: N/A | D19: P2P | E19: N/A | F19: P2P | G19: N/A | H19: 0.0084 | I19: 46092 | J19: N/A | K19: N/A | L19: P2P | M19: N/A | N19: P2P | O19: P2P | P19: 0.0308 | Q19: =P19-H19 -> 0.0224 | S19: 46092 | T19: N/A | U19: N/A | V19: N/A | W19: N/A | X19: 0.03 | Y19: N/A | Z19: 0.0117 | AA19: 46092 | AB19: N/A | AC19: N/A | AD19: N/A | AE19: N/A | AF19: N/A | AG19: N/A | AH19: 0.025 | AI19: =AH19-Z19 -> 0.0133 | AK19: 46092 | AL19: 0.02 | AP19: N/A | AQ19: 0.0265 | AR19: 0.0067 | AS19: 46092 | AT19: 0.032 | AU19: 0.0409 | AV19: 0.036 | AW19: 0.049 | AX19: 0.0533 | AY19: 0.061 | AZ19: 0.0354 | BA19: =AZ19-AR19 -> 0.0287 | BC19: 46092 | BD19: 0.0078 | BE19: 0.0079 | BF19: 0.0081 | BJ19: 0.0071 | BK19: 46092 | BL19: 0.0386 | BN19: 0.0548 | BR19: 0.0315 | BS19: =BR19-BJ19 -> 0.0244
A20: 46093 | B20: N/A | C20: N/A | D20: P2P | E20: N/A | F20: P2P | G20: N/A | H20: 0.0087 | I20: 46093 | J20: N/A | K20: N/A | L20: P2P | M20: N/A | N20: P2P | O20: P2P | P20: 0.0313 | Q20: =P20-H20 -> 0.0226 | S20: 46093 | T20: N/A | U20: N/A | V20: N/A | W20: N/A | X20: 0.03 | Y20: N/A | Z20: 0.0115 | AA20: 46093 | AB20: N/A | AC20: N/A | AD20: N/A | AE20: N/A | AF20: N/A | AG20: N/A | AH20: 0.025 | AI20: =AH20-Z20 -> 0.0135 | AK20: 46093 | AL20: 0.02 | AP20: 0.0251 | AQ20: 0.0265 | AR20: 0.0066 | AS20: 46093 | AT20: 0.032 | AU20: 0.0409 | AV20: 0.031 | AW20: 0.05 | AX20: 0.0533 | AY20: 0.066 | AZ20: 0.0353 | BA20: =AZ20-AR20 -> 0.0287 | BC20: 46093 | BD20: 0.0073 | BE20: 0.0073 | BF20: 0.0075 | BJ20: 0.0071 | BK20: 46093 | BL20: 0.0386 | BN20: 0.0548 | BR20: 0.0316 | BS20: =BR20-BJ20 -> 0.0245
A21: 46094 | B21: N/A | C21: N/A | D21: P2P | E21: N/A | F21: P2P | G21: N/A | H21: 0.0083 | I21: 46094 | J21: N/A | K21: N/A | L21: P2P | M21: N/A | N21: P2P | O21: P2P | P21: 0.0306 | Q21: =P21-H21 -> 0.0223 | S21: 46094 | T21: N/A | U21: N/A | V21: N/A | W21: N/A | X21: 0.03 | Y21: N/A | Z21: 0.0116 | AA21: 46094 | AB21: N/A | AC21: N/A | AD21: N/A | AE21: N/A | AF21: N/A | AG21: N/A | AH21: 0.025 | AI21: =AH21-Z21 -> 0.0134 | AK21: 46094 | AL21: 0.02 | AP21: 0.0251 | AQ21: 0.0265 | AR21: 0.0066 | AS21: 46094 | AT21: 0.033 | AU21: 0.0407 | AV21: 0.038 | AW21: 0.0469 | AX21: 0.0479 | AY21: 0.065 | AZ21: 0.0345 | BA21: =AZ21-AR21 -> 0.0279 | BC21: 46094 | BD21: 0.0072 | BE21: 0.0072 | BF21: 0.0072 | BJ21: 0.0071 | BK21: 46094 | BL21: 0.0386 | BN21: 0.0548 | BR21: 0.0314 | BS21: =BR21-BJ21 -> 0.0243
A22: 46095 | B22: N/A | C22: N/A | D22: P2P | E22: N/A | F22: P2P | G22: N/A | H22: 0.008 | I22: 46095 | J22: N/A | K22: N/A | L22: P2P | M22: N/A | N22: P2P | O22: P2P | P22: 0.0299 | Q22: =P22-H22 -> 0.0219 | S22: 46095 | T22: N/A | U22: N/A | V22: N/A | W22: N/A | X22: 0.035 | Y22: N/A | Z22: 0.0115 | AA22: 46095 | AB22: N/A | AC22: N/A | AD22: N/A | AE22: N/A | AF22: N/A | AG22: N/A | AH22: 0.025 | AI22: =AH22-Z22 -> 0.0135 | AK22: 46095 | AL22: 0.02 | AP22: N/A | AQ22: 0.0265 | AR22: 0.0064 | AS22: 46095 | AT22: 0.0328 | AU22: 0.0408 | AV22: 0.04 | AW22: 0.044 | AX22: 0.0533 | AY22: 0.062 | AZ22: 0.034 | BA22: =AZ22-AR22 -> 0.0276 | BC22: 46095 | BD22: 0.0072 | BE22: 0.0073 | BF22: 0.0077 | BJ22: 0.0074 | BK22: 46095 | BL22: 0.0386 | BN22: 0.0548 | BR22: 0.032 | BS22: =BR22-BJ22 -> 0.0246
A23: 46096 | B23: N/A | C23: N/A | D23: P2P | E23: N/A | F23: P2P | G23: N/A | H23: 0.0082 | I23: 46096 | J23: N/A | K23: N/A | L23: P2P | M23: N/A | N23: P2P | O23: P2P | P23: 0.0321 | Q23: =P23-H23 -> 0.0239 | S23: 46096 | T23: N/A | U23: N/A | V23: N/A | W23: N/A | X23: 0.035 | Y23: N/A | Z23: 0.0119 | AA23: 46096 | AB23: N/A | AC23: N/A | AD23: N/A | AE23: N/A | AF23: N/A | AG23: N/A | AH23: 0.025 | AI23: =AH23-Z23 -> 0.0131 | AK23: 46096 | AL23: 0.02 | AP23: N/A | AQ23: 0.0265 | AR23: 0.0068 | AS23: 46096 | AT23: 0.032 | AU23: 0.0395 | AV23: 0.032 | AW23: 0.044 | AX23: 0.0533 | AY23: 0.0615 | AZ23: 0.0345 | BA23: =AZ23-AR23 -> 0.0277 | BC23: 46096 | BD23: 0.0072 | BE23: 0.0073 | BF23: 0.0076 | BJ23: 0.0075 | BK23: 46096 | BL23: 0.0386 | BN23: 0.0548 | BR23: 0.0311 | BS23: =BR23-BJ23 -> 0.0236
A24: 46097 | B24: N/A | C24: N/A | D24: P2P | E24: N/A | F24: P2P | G24: N/A | H24: 0.0098 | I24: 46097 | J24: N/A | K24: N/A | L24: P2P | M24: N/A | N24: P2P | O24: P2P | P24: 0.0332 | Q24: =P24-H24 -> 0.0234 | S24: 46097 | T24: N/A | U24: N/A | V24: N/A | W24: N/A | X24: 0.035 | Y24: N/A | Z24: 0.0121 | AA24: 46097 | AB24: N/A | AC24: N/A | AD24: N/A | AE24: N/A | AF24: N/A | AG24: N/A | AH24: 0.025 | AI24: =AH24-Z24 -> 0.0129 | AK24: 46097 | AL24: 0.02 | AP24: N/A | AQ24: 0.0265 | AR24: 0.007 | AS24: 46097 | AT24: 0.032 | AU24: 0.0399 | AV24: 0.04 | AW24: 0.0447 | AX24: 0.051 | AY24: 0.062 | AZ24: 0.0349 | BA24: =AZ24-AR24 -> 0.0279 | BC24: 46097 | BD24: 0.0072 | BE24: 0.0073 | BF24: 0.0076 | BJ24: 0.0076 | BK24: 46097 | BL24: 0.0386 | BN24: 0.0548 | BR24: 0.0311 | BS24: =BR24-BJ24 -> 0.0235
A25: 46098 | B25: N/A | C25: N/A | D25: P2P | E25: N/A | F25: P2P | G25: N/A | H25: 0.0099 | I25: 46098 | J25: N/A | K25: N/A | L25: P2P | M25: N/A | N25: P2P | O25: P2P | P25: 0.0335 | Q25: =P25-H25 -> 0.0236 | S25: 46098 | T25: N/A | U25: N/A | V25: N/A | W25: N/A | X25: 0.035 | Y25: N/A | Z25: 0.0122 | AA25: 46098 | AB25: N/A | AC25: N/A | AD25: N/A | AE25: N/A | AF25: N/A | AG25: N/A | AH25: 0.025 | AI25: =AH25-Z25 -> 0.0128 | AK25: 46098 | AL25: 0.02 | AP25: N/A | AQ25: 0.0265 | AR25: 0.0076 | AS25: 46098 | AT25: 0.03 | AU25: 0.0394 | AV25: 0.042 | AW25: 0.0439 | AX25: 0.0507 | AY25: 0.062 | AZ25: 0.0385 | BA25: =AZ25-AR25 -> 0.0309 | BC25: 46098 | BD25: 0.0072 | BE25: 0.0073 | BF25: 0.0076 | BJ25: 0.0073 | BK25: 46098 | BL25: 0.0386 | BN25: 0.0548 | BR25: 0.0311 | BS25: =BR25-BJ25 -> 0.0238
A26: 46099 | B26: N/A | C26: N/A | D26: P2P | E26: N/A | F26: P2P | G26: N/A | H26: 0.0092 | I26: 46099 | J26: N/A | K26: N/A | L26: P2P | M26: N/A | N26: P2P | O26: P2P | P26: 0.0323 | Q26: =P26-H26 -> 0.0231 | S26: 46099 | T26: N/A | U26: N/A | V26: N/A | W26: N/A | X26: 0.035 | Y26: N/A | Z26: 0.0122 | AA26: 46099 | AB26: N/A | AC26: N/A | AD26: N/A | AE26: N/A | AF26: N/A | AG26: N/A | AH26: 0.025 | AI26: =AH26-Z26 -> 0.0128 | AK26: 46099 | AL26: 0.02 | AP26: N/A | AQ26: 0.0265 | AR26: 0.0072 | AS26: 46099 | AT26: 0.035 | AU26: 0.042 | AV26: 0.04 | AW26: 0.042 | AX26: 0.0505 | AY26: 0.0659 | AZ26: 0.0357 | BA26: =AZ26-AR26 -> 0.0285 | BC26: 46099 | BD26: 0.0072 | BE26: 0.0073 | BF26: 0.0076 | BJ26: 0.0073 | BK26: 46099 | BL26: 0.0386 | BN26: 0.0548 | BR26: 0.0312 | BS26: =BR26-BJ26 -> 0.0239
A27: 46100 | B27: N/A | C27: N/A | D27: P2P | E27: N/A | F27: P2P | G27: N/A | H27: 0.0082 | I27: 46100 | J27: N/A | K27: N/A | L27: P2P | M27: N/A | N27: P2P | O27: P2P | P27: 0.0305 | Q27: =P27-H27 -> 0.0223 | S27: 46100 | T27: N/A | U27: N/A | V27: N/A | W27: N/A | X27: 0.035 | Y27: N/A | Z27: 0.0115 | AA27: 46100 | AB27: N/A | AC27: N/A | AD27: N/A | AE27: N/A | AF27: N/A | AG27: N/A | AH27: 0.025 | AI27: =AH27-Z27 -> 0.0135 | AK27: 46100 | AL27: 0.02 | AP27: N/A | AQ27: 0.0265 | AR27: 0.006 | AS27: 46100 | AT27: 0.0342 | AU27: 0.042 | AV27: 0.035 | AW27: 0.044 | AX27: 0.0507 | AY27: 0.0658 | AZ27: 0.0343 | BA27: =AZ27-AR27 -> 0.0283 | BC27: 46100 | BD27: 0.0072 | BE27: 0.0073 | BF27: 0.0076 | BJ27: 0.0074 | BK27: 46100 | BL27: 0.0386 | BN27: 0.0548 | BR27: 0.0312 | BS27: =BR27-BJ27 -> 0.0238
A28: 46101 | B28: N/A | C28: N/A | D28: P2P | E28: N/A | F28: P2P | G28: N/A | H28: 0.007 | I28: 46101 | J28: N/A | K28: N/A | L28: P2P | M28: N/A | N28: P2P | O28: P2P | P28: 0.0287 | Q28: =P28-H28 -> 0.0217 | S28: 46101 | T28: N/A | U28: N/A | V28: N/A | W28: N/A | X28: 0.035 | Y28: N/A | Z28: 0.0112 | AA28: 46101 | AB28: N/A | AC28: N/A | AD28: N/A | AE28: N/A | AF28: N/A | AG28: N/A | AH28: 0.025 | AI28: =AH28-Z28 -> 0.0138 | AK28: 46101 | AL28: 0.02 | AP28: 0.026 | AQ28: 0.027 | AR28: 0.006 | AS28: 46101 | AT28: 0.0342 | AU28: 0.04 | AV28: 0.034 | AW28: 0.044 | AX28: 0.05 | AY28: 0.0658 | AZ28: 0.034 | BA28: =AZ28-AR28 -> 0.028 | BC28: 46101 | BD28: 0.0072 | BE28: 0.0073 | BF28: 0.0074 | BJ28: 0.0078 | BK28: 46101 | BL28: 0.0378 | BN28: 0.0548 | BR28: 0.0318 | BS28: =BR28-BJ28 -> 0.024
A29: 46102 | B29: N/A | C29: N/A | D29: P2P | E29: N/A | F29: P2P | G29: N/A | H29: 0.0075 | I29: 46102 | J29: N/A | K29: N/A | L29: P2P | M29: N/A | N29: P2P | O29: P2P | P29: 0.029 | Q29: =P29-H29 -> 0.0215 | S29: 46102 | T29: N/A | U29: N/A | V29: N/A | W29: N/A | X29: 0.035 | Y29: N/A | Z29: 0.0112 | AA29: 46102 | AB29: N/A | AC29: N/A | AD29: N/A | AE29: N/A | AF29: N/A | AG29: N/A | AH29: 0.025 | AI29: =AH29-Z29 -> 0.0138 | AK29: 46102 | AL29: 0.02 | AP29: 0.026 | AQ29: 0.027 | AR29: 0.006 | AS29: 46102 | AT29: 0.0342 | AU29: 0.034 | AV29: 0.0349 | AW29: 0.043 | AX29: 0.05 | AY29: 0.0683 | AZ29: 0.0333 | BA29: =AZ29-AR29 -> 0.0273 | BC29: 46102 | BD29: 0.0072 | BE29: 0.0072 | BF29: 0.0072 | BJ29: 0.007 | BK29: 46102 | BL29: 0.0378 | BN29: 0.0548 | BR29: 0.0286 | BS29: =BR29-BJ29 -> 0.0216
A30: 46103 | B30: N/A | C30: N/A | D30: P2P | E30: N/A | F30: P2P | G30: N/A | H30: 0.0071 | I30: 46103 | J30: N/A | K30: N/A | L30: P2P | M30: N/A | N30: P2P | O30: P2P | P30: 0.0283 | Q30: =P30-H30 -> 0.0212 | S30: 46103 | T30: N/A | U30: N/A | V30: N/A | W30: N/A | X30: 0.035 | Y30: N/A | Z30: 0.0109 | AA30: 46103 | AB30: N/A | AC30: N/A | AD30: N/A | AE30: N/A | AF30: N/A | AG30: N/A | AH30: 0.025 | AI30: =AH30-Z30 -> 0.0141 | AK30: 46103 | AL30: 0.02 | AP30: 0.026 | AQ30: 0.027 | AR30: 0.006 | AS30: 46103 | AT30: 0.031 | AU30: 0.0394 | AV30: 0.0349 | AW30: 0.044 | AX30: 0.05 | AY30: 0.0681 | AZ30: 0.0333 | BA30: =AZ30-AR30 -> 0.0273 | BC30: 46103 | BD30: 0.0072 | BE30: 0.0072 | BF30: 0.0072 | BJ30: 0.007 | BK30: 46103 | BL30: 0.0376 | BN30: 0.0548 | BR30: 0.0286 | BS30: =BR30-BJ30 -> 0.0216
A31: 46104 | B31: N/A | C31: N/A | D31: P2P | E31: N/A | F31: P2P | G31: N/A | H31: 0.0074 | I31: 46104 | J31: N/A | K31: N/A | L31: P2P | M31: N/A | N31: P2P | O31: P2P | P31: 0.0288 | Q31: =P31-H31 -> 0.0214 | S31: 46104 | T31: N/A | U31: N/A | V31: N/A | W31: N/A | X31: 0.035 | Y31: N/A | Z31: 0.0111 | AA31: 46104 | AB31: N/A | AC31: N/A | AD31: N/A | AE31: N/A | AF31: N/A | AG31: N/A | AH31: 0.025 | AI31: =AH31-Z31 -> 0.0139 | AK31: 46104 | AL31: 0.025 | AP31: 0.026 | AQ31: 0.027 | AR31: 0.006 | AS31: 46104 | AT31: 0.03 | AU31: 0.035 | AV31: 0.035 | AW31: 0.044 | AX31: 0.0575 | AY31: 0.0684 | AZ31: 0.0333 | BA31: =AZ31-AR31 -> 0.0273 | BC31: 46104 | BD31: 0.0071 | BE31: 0.0072 | BF31: 0.0076 | BJ31: 0.0074 | BK31: 46104 | BL31: 0.0376 | BN31: 0.0548 | BR31: 0.0301 | BS31: =BR31-BJ31 -> 0.0227
A32: 46105 | B32: N/A | C32: N/A | D32: P2P | E32: N/A | F32: P2P | G32: N/A | H32: 0.0076 | I32: 46105 | J32: N/A | K32: N/A | L32: P2P | M32: N/A | N32: P2P | O32: P2P | P32: 0.0292 | Q32: =P32-H32 -> 0.0216 | S32: 46105 | T32: N/A | U32: N/A | V32: N/A | W32: N/A | X32: 0.035 | Y32: N/A | Z32: 0.011 | AA32: 46105 | AB32: N/A | AC32: N/A | AD32: N/A | AE32: N/A | AF32: N/A | AG32: N/A | AH32: 0.025 | AI32: =AH32-Z32 -> 0.014 | AK32: 46105 | AL32: 0.02 | AP32: 0.026 | AQ32: 0.027 | AR32: 0.006 | AS32: 46105 | AT32: 0.03 | AU32: 0.035 | AV32: 0.0349 | AW32: 0.0429 | AX32: 0.06 | AY32: 0.0687 | AZ32: 0.0333 | BA32: =AZ32-AR32 -> 0.0273 | BC32: 46105 | BD32: 0.0071 | BE32: 0.0072 | BF32: 0.0074 | BJ32: 0.0072 | BK32: 46105 | BL32: 0.0376 | BN32: 0.0548 | BR32: 0.0297 | BS32: =BR32-BJ32 -> 0.0225
A33: 46106 | B33: N/A | C33: N/A | D33: P2P | E33: N/A | F33: P2P | G33: N/A | H33: 0.0074 | I33: 46106 | J33: N/A | K33: N/A | L33: P2P | M33: N/A | N33: P2P | O33: P2P | P33: 0.0288 | Q33: =P33-H33 -> 0.0214 | S33: 46106 | T33: N/A | U33: N/A | V33: N/A | W33: N/A | X33: 0.035 | Y33: N/A | Z33: 0.0111 | AA33: 46106 | AB33: N/A | AC33: N/A | AD33: N/A | AE33: N/A | AF33: N/A | AG33: N/A | AH33: 0.025 | AI33: =AH33-Z33 -> 0.0139 | AK33: 46106 | AL33: 0.02 | AP33: 0.026 | AQ33: 0.027 | AR33: 0.006 | AS33: 46106 | AT33: 0.03 | AU33: 0.033 | AV33: 0.028 | AW33: 0.0429 | AX33: 0.0656 | AY33: 0.043 | AZ33: 0.0333 | BA33: =AZ33-AR33 -> 0.0273 | BC33: 46106 | BD33: 0.0071 | BE33: 0.0072 | BF33: 0.0075 | BJ33: 0.0073 | BK33: 46106 | BL33: 0.0376 | BN33: 0.0548 | BR33: 0.0299 | BS33: =BR33-BJ33 -> 0.0226
A34: 46107 | B34: N/A | C34: N/A | D34: P2P | E34: N/A | F34: P2P | G34: N/A | H34: 0.0078 | I34: 46107 | J34: N/A | K34: N/A | L34: P2P | M34: N/A | N34: P2P | O34: P2P | P34: 0.0298 | Q34: =P34-H34 -> 0.022 | S34: 46107 | T34: N/A | U34: N/A | V34: N/A | W34: N/A | X34: 0.03 | Y34: N/A | Z34: 0.0111 | AA34: 46107 | AB34: N/A | AC34: N/A | AD34: N/A | AE34: N/A | AF34: N/A | AG34: N/A | AH34: 0.025 | AI34: =AH34-Z34 -> 0.0139 | AK34: 46107 | AL34: 0.02 | AP34: 0.026 | AQ34: 0.027 | AR34: 0.006 | AS34: 46107 | AT34: 0.03 | AU34: 0.032 | AV34: 0.042 | AW34: 0.0438 | AX34: 0.0649 | AY34: 0.048 | AZ34: 0.0332 | BA34: =AZ34-AR34 -> 0.0272 | BC34: 46107 | BD34: 0.0071 | BE34: 0.0072 | BF34: 0.0075 | BJ34: 0.0074 | BK34: 46107 | BL34: 0.0376 | BN34: 0.0548 | BR34: 0.0302 | BS34: =BR34-BJ34 -> 0.0228
A35: 46108 | B35: N/A | C35: N/A | D35: P2P | E35: N/A | F35: P2P | G35: N/A | H35: 0.0079 | I35: 46108 | J35: N/A | K35: N/A | L35: P2P | M35: N/A | N35: P2P | O35: P2P | P35: 0.0299 | Q35: =P35-H35 -> 0.022 | S35: 46108 | T35: N/A | U35: N/A | V35: N/A | W35: N/A | X35: 0.03 | Y35: N/A | Z35: 0.0117 | AA35: 46108 | AB35: N/A | AC35: N/A | AD35: N/A | AE35: N/A | AF35: N/A | AG35: N/A | AH35: 0.025 | AI35: =AH35-Z35 -> 0.0133 | AK35: 46108 | AL35: 0.02 | AP35: 0.026 | AQ35: 0.027 | AR35: 0.006 | AS35: 46108 | AT35: 0.03 | AU35: 0.033 | AV35: 0.0349 | AW35: 0.044 | AX35: 0.0565 | AY35: 0.0688 | AZ35: 0.0338 | BA35: =AZ35-AR35 -> 0.0278 | BC35: 46108 | BD35: 0.0071 | BE35: 0.0072 | BF35: 0.0075 | BJ35: 0.0075 | BK35: 46108 | BL35: 0.0376 | BN35: 0.0548 | BR35: 0.0302 | BS35: =BR35-BJ35 -> 0.0227
A36: 46109 | B36: N/A | C36: N/A | D36: P2P | E36: N/A | F36: P2P | G36: N/A | H36: 0.0079 | I36: 46109 | J36: N/A | K36: N/A | L36: P2P | M36: N/A | N36: P2P | O36: P2P | P36: 0.0298 | Q36: =P36-H36 -> 0.0219 | S36: 46109 | T36: N/A | U36: N/A | V36: N/A | W36: N/A | X36: 0.03 | Y36: N/A | Z36: 0.0108 | AA36: 46109 | AB36: N/A | AC36: N/A | AD36: N/A | AE36: N/A | AF36: N/A | AG36: N/A | AH36: 0.025 | AI36: =AH36-Z36 -> 0.0142 | AK36: 46109 | AL36: 0.02 | AP36: N/A | AQ36: 0.027 | AR36: 0.006 | AS36: 46109 | AT36: 0.03 | AU36: 0.033 | AV36: 0.026 | AW36: 0.044 | AX36: 0.0261 | AY36: 0.0251 | AZ36: 0.0339 | BA36: =AZ36-AR36 -> 0.0279 | BC36: 46109 | BD36: 0.0071 | BE36: 0.0072 | BF36: 0.0075 | BJ36: 0.0073 | BK36: 46109 | BL36: 0.0376 | BN36: 0.0548 | BR36: 0.0298 | BS36: =BR36-BJ36 -> 0.0225
A37: 46110 | B37: N/A | C37: N/A | D37: P2P | E37: N/A | F37: P2P | G37: N/A | H37: 0.0076 | I37: 46110 | J37: N/A | K37: N/A | L37: P2P | M37: N/A | N37: P2P | O37: P2P | P37: 0.0299 | Q37: =P37-H37 -> 0.0223 | S37: 46110 | T37: N/A | U37: N/A | V37: N/A | W37: N/A | X37: 0.03 | Y37: N/A | Z37: 0.0107 | AA37: 46110 | AB37: N/A | AC37: N/A | AD37: N/A | AE37: N/A | AF37: N/A | AG37: N/A | AH37: 0.025 | AI37: =AH37-Z37 -> 0.0143 | AK37: 46110 | AL37: N/A | AP37: N/A | AQ37: 0.027 | AR37: 0.006 | AS37: 46110 | AT37: 0.03 | AU37: 0.033 | AV37: 0.032 | AW37: 0.044 | AX37: 0.056 | AY37: 0.06 | AZ37: 0.033 | BA37: =AZ37-AR37 -> 0.027 | BC37: 46110 | BD37: 0.0071 | BE37: 0.0072 | BF37: 0.0074 | BJ37: 0.0071 | BK37: 46110 | BL37: 0.0376 | BN37: 0.0548 | BR37: 0.0297 | BS37: =BR37-BJ37 -> 0.0226
A38: 46111 | B38: N/A | C38: N/A | D38: P2P | E38: N/A | F38: P2P | G38: N/A | H38: 0.0079 | I38: 46111 | J38: N/A | K38: N/A | L38: P2P | M38: N/A | N38: P2P | O38: P2P | P38: 0.0298 | Q38: =P38-H38 -> 0.0219 | S38: 46111 | T38: N/A | U38: N/A | V38: N/A | W38: N/A | X38: 0.03 | Y38: N/A | Z38: 0.0113 | AA38: 46111 | AB38: N/A | AC38: N/A | AD38: N/A | AE38: N/A | AF38: N/A | AG38: N/A | AH38: 0.025 | AI38: =AH38-Z38 -> 0.0137 | AK38: 46111 | AL38: N/A | AP38: N/A | AQ38: 0.027 | AR38: 0.006 | AS38: 46111 | AT38: 0.03 | AU38: 0.0327 | AV38: 0.0399 | AW38: 0.0439 | AX38: 0.0649 | AY38: 0.0687 | AZ38: 0.0334 | BA38: =AZ38-AR38 -> 0.0274 | BC38: 46111 | BD38: 0.0071 | BE38: 0.0071 | BF38: 0.0074 | BJ38: 0.0073 | BK38: 46111 | BL38: 0.0376 | BN38: 0.0548 | BR38: 0.0297 | BS38: =BR38-BJ38 -> 0.0224
A39: 46112 | B39: N/A | C39: N/A | D39: P2P | E39: N/A | F39: P2P | G39: N/A | H39: 0.0083 | I39: 46112 | J39: N/A | K39: N/A | L39: P2P | M39: N/A | N39: P2P | O39: P2P | P39: 0.0305 | Q39: =P39-H39 -> 0.0222 | S39: 46112 | T39: N/A | U39: N/A | V39: N/A | W39: N/A | X39: 0.03 | Y39: N/A | Z39: 0.0102 | AA39: 46112 | AB39: N/A | AC39: N/A | AD39: N/A | AE39: N/A | AF39: N/A | AG39: N/A | AH39: 0.025 | AI39: =AH39-Z39 -> 0.0148 | AK39: 46112 | AL39: N/A | AP39: N/A | AQ39: 0.027 | AR39: 0.006 | AS39: 46112 | AT39: 0.0253 | AU39: 0.032 | AV39: 0.04 | AW39: 0.0315 | AX39: 0.0649 | AY39: 0.0684 | AZ39: 0.0341 | BA39: =AZ39-AR39 -> 0.0281 | BC39: 46112 | BD39: 0.0071 | BE39: 0.0071 | BF39: 0.0074 | BJ39: 0.0084 | BK39: 46112 | BL39: 0.0376 | BN39: 0.0548 | BR39: 0.0311 | BS39: =BR39-BJ39 -> 0.0227
A40: 46113 | B40: N/A | C40: N/A | D40: P2P | E40: N/A | F40: P2P | G40: N/A | H40: 0.0083 | I40: 46113 | J40: N/A | K40: N/A | L40: P2P | M40: N/A | N40: P2P | O40: P2P | P40: 0.0305 | Q40: =P40-H40 -> 0.0222 | S40: 46113 | T40: N/A | U40: N/A | V40: N/A | W40: N/A | X40: 0.03 | Y40: N/A | Z40: 0.0105 | AA40: 46113 | AB40: N/A | AC40: N/A | AD40: N/A | AE40: N/A | AF40: N/A | AG40: N/A | AH40: 0.025 | AI40: =AH40-Z40 -> 0.0145 | AK40: 46113 | AL40: 0.02 | AP40: N/A | AQ40: 0.0265 | AR40: 0.006 | AS40: 46113 | AT40: 0.043 | AU40: 0.0326 | AV40: 0.04 | AW40: 0.0438 | AX40: 0.0599 | AY40: 0.0669 | AZ40: 0.0339 | BA40: =AZ40-AR40 -> 0.0279 | BC40: 46113 | BD40: 0.0072 | BE40: 0.0072 | BF40: 0.0074 | BJ40: 0.0083 | BK40: 46113 | BL40: 0.0376 | BN40: 0.0548 | BR40: 0.0306 | BS40: =BR40-BJ40 -> 0.0223
...

Sheet Günlük taslak
A1: 46077 | B1: 7 | C1: 14 | D1: 30 | E1: 60 | F1: 90 | G1: Flexible | H1: Annual | J1: 46087 | K1: 7 | L1: 14 | M1: 30 | N1: 60 | O1: 90 | P1: Flexible | Q1: Annual | S1: 46097 | T1: 7 | U1: 14 | V1: 30 | W1: 60 | X1: 90 | Y1: Flexible | Z1: Annual | AB1: 46107 | AC1: 7 | AD1: 14 | AE1: 30 | AF1: 60 | AG1: 90 | AH1: Flexible | AI1: Annual | AK1: 46117 | AL1: 7 | AM1: 14 | AN1: 30 | AO1: 60 | AP1: 90 | AQ1: Flexible | AR1: Annual
B2: =(1+B4)^(365/7)-1 -> 0.030968576 | C2: =(1+C4)^(365/14)-1 -> 0.030968576 | D2: =(1+D4)^(365/30)-1 -> 0.030968576 | E2: =(1+E4)^(365/60)-1 -> 0.030968576 | F2: =(1+F4)^(365/90)-1 -> 0.030968576
B3: =B4*(365/B1) -> 0.030507647 | C3: =C4*(365/14) -> 0.030516572 | D3: =D4*(365/30) -> 0.030536984 | E3: =E4*(365/60) -> 0.030575306 | F3: =F4*(365/90) -> 0.030613693 | K3: =K4*365/K1 -> 0.032308576 | L3: =L4*365/L1 -> 0.032318586 | M3: =M4*365/M1 -> 0.03234148 | N3: =N4*365/N1 -> 0.032384465 | O3: =O4*365/O1 -> 0.032427526 | T3: =T4*365/T1 -> 0.033209061 | U3: =U4*365/U1 -> 0.033219636 | V3: =V4*365/V1 -> 0.033243825 | W3: =W4*365/W1 -> 0.033289242 | X3: =X4*365/X1 -> 0.033334742 | AK3: Binance | AL3: =((1+$AR3)^(AL1/365)-1)*365/AL1 -> 0.0310079 | AM3: =((1+$AR3)^(AM1/365)-1)*365/AM1 -> 0.03101712 | AN3: =((1+$AR3)^(AN1/365)-1)*365/AN1 -> 0.031038207 | AO3: =((1+$AR3)^(AO1/365)-1)*365/AO1 -> 0.031077798 | AP3: =((1+$AR3)^(AP1/365)-1)*365/AP1 -> 0.031117455 | AQ3: 0.031 | AR3: =(1+AQ3/365)^365-1 -> 0.031484146
A4: Binance | B4: =(1+$H4)^(B1/365)-1 -> 0.00058507816 | C4: =(1+$H4)^(C1/365)-1 -> 0.0011704986 | D4: =(1+$H4)^(D1/365)-1 -> 0.0025098891 | E4: =(1+$H4)^(E1/365)-1 -> 0.0050260777 | F4: =(1+$H4)^(F1/365)-1 -> 0.0075485817 | G4: =3.05/100 -> 0.0305 | H4: =(1+G4/365)^365-1 -> 0.030968576 | J4: Binance | K4: =(1+$Q4)^(K1/365)-1 -> 0.00061961653 | L4: =(1+$Q4)^(L1/365)-1 -> 0.001239617 | M4: =(1+$Q4)^(M1/365)-1 -> 0.0026582038 | N4: =(1+$Q4)^(N1/365)-1 -> 0.0053234737 | O4: =(1+$Q4)^(O1/365)-1 -> 0.0079958284 | P4: 0.0323 | Q4: =(1+P4/365)^365-1 -> 0.032825831 | S4: Binance | T4: =(1+$Z4)^(T1/365)-1 -> 0.0006368861 | U4: =(1+$Z4)^(U1/365)-1 -> 0.0012741778 | V4: =(1+$Z4)^(V1/365)-1 -> 0.0027323692 | W4: =(1+$Z4)^(W1/365)-1 -> 0.0054722042 | X4: =(1+$Z4)^(X1/365)-1 -> 0.0082195254 | Y4: 0.0332 | Z4: =(1+Y4/365)^365-1 -> 0.033755709 | AB4: Binance | AC4: =((1+$AI4)^(AC1/365)-1)*365/AC1 -> 0.0298073 | AD4: =((1+$AI4)^(AD1/365)-1)*365/AD1 -> 0.02981582 | AE4: =((1+$AI4)^(AE1/365)-1)*365/AE1 -> 0.029835305 | AF4: =((1+$AI4)^(AF1/365)-1)*365/AF1 -> 0.029871887 | AG4: =((1+$AI4)^(AG1/365)-1)*365/AG1 -> 0.029908528 | AH4: 0.0298 | AI4: =(1+AH4/365)^365-1 -> 0.03024721 | AK4: Bybit | AL4: 0.031 | AM4: 0.03 | AN4: 0.044 | AO4: 0.057 | AP4: 0.0597 | AQ4: 0.0342 | AR4: =(1+AQ4/365)^365-1 -> 0.034789886
A5: Bybit | B5: 3.20% | C5: 3.20% | D5: 4.50% | E5: 5.10% | F5: 5.88% | G5: =3.49/100 -> 0.0349 | H5: =(1+G5/365)^365-1 -> 0.035514424 | J5: Bybit | K5: 0.039 | L5: 0.0345 | M5: 0.04 | N5: 0.0572 | O5: 0.0579 | P5: 0.0356 | Q5: =(1+P5/365)^365-1 -> 0.036239468 | S5: Bybit | T5: 0.032 | U5: 0.0399 | V5: 0.04 | W5: 0.0447 | X5: 0.051 | Y5: 0.0345 | Z5: =(1+Y5/365)^365-1 -> 0.035100341 | AB5: Bybit | AC5: ='Daily Data'!AT34 -> 0.03 | AD5: ='Daily Data'!AU34 -> 0.032 | AE5: ='Daily Data'!AV34 -> 0.042 | AF5: ='Daily Data'!AW34 -> 0.0438 | AG5: ='Daily Data'!AX34 -> 0.0649 | AH5: 0.0332 | AI5: =(1+AH5/365)^365-1 -> 0.033755709
B6: =(1+B8)^(365/7)-1 -> 0.030145392 | C6: =(1+C8)^(365/14)-1 -> 0.030145392 | D6: =(1+D8)^(365/30)-1 -> 0.030145392 | E6: =(1+E8)^(365/60)-1 -> 0.030145392 | F6: =(1+F8)^(365/90)-1 -> 0.030145392 | AK6: OKX | AL6: =((1+$AR6)^(AL1/365)-1)*365/AL1 -> 0.025005138 | AM6: =((1+$AR6)^(AM1/365)-1)*365/AM1 -> 0.025011133 | AN6: =((1+$AR6)^(AN1/365)-1)*365/AN1 -> 0.025024845 | AO6: =((1+$AR6)^(AO1/365)-1)*365/AO1 -> 0.025050581 | AP6: =((1+$AR6)^(AP1/365)-1)*365/AP1 -> 0.025076352 | AQ6: 0.025 | AR6: =(1+AQ6/365)^365-1 -> 0.025314243
B7: =B8*(365/7) -> 0.02970841 | C7: =C8*(365/14) -> 0.029716873 | D7: =D8*(365/30) -> 0.029736229 | E7: =E8*(365/60) -> 0.029772568 | F7: =F8*(365/90) -> 0.029808966 | K7: =K8*365/K1 -> 0.025005138 | L7: =L8*365/L1 -> 0.025011133 | M7: =M8*365/M1 -> 0.025024845 | N7: =N8*365/N1 -> 0.025050581 | O7: =O8*365/O1 -> 0.025076352 | T7: =T8*365/T1 -> 0.025005138 | U7: =U8*365/U1 -> 0.025011133 | V7: =V8*365/V1 -> 0.025024845 | W7: =W8*365/W1 -> 0.025050581 | X7: =X8*365/X1 -> 0.025076352
A8: OKX | B8: =(1+$H8)^(B1/365)-1 -> 0.00056975032 | C8: =(1+$H8)^(C1/365)-1 -> 0.0011398253 | D8: =(1+$H8)^(D1/365)-1 -> 0.0024440736 | E8: =(1+$H8)^(E1/365)-1 -> 0.0048941208 | F8: =(1+$H8)^(F1/365)-1 -> 0.007350156 | G8: =2.97/100 -> 0.0297 | H8: =(1+G8/8760)^8760-1 -> 0.030145392 | J8: OKX | K8: =(1+$Q8)^(K1/365)-1 -> 0.00047955058 | L8: =(1+$Q8)^(L1/365)-1 -> 0.00095933114 | M8: =(1+$Q8)^(M1/365)-1 -> 0.0020568365 | N8: =(1+$Q8)^(N1/365)-1 -> 0.0041179037 | O8: =(1+$Q8)^(O1/365)-1 -> 0.0061832101 | P8: 0.025 | Q8: =(1+P8/365)^365-1 -> 0.025314243 | S8: OKX | T8: =(1+$Z8)^(T1/365)-1 -> 0.00047955058 | U8: =(1+$Z8)^(U1/365)-1 -> 0.00095933114 | V8: =(1+$Z8)^(V1/365)-1 -> 0.0020568365 | W8: =(1+$Z8)^(W1/365)-1 -> 0.0041179037 | X8: =(1+$Z8)^(X1/365)-1 -> 0.0061832101 | Y8: 0.025 | Z8: =(1+Y8/365)^365-1 -> 0.025314243 | AB8: OKX | AC8: =((1+$AI8)^(AC1/365)-1)*365/AC1 -> 0.025005138 | AD8: =((1+$AI8)^(AD1/365)-1)*365/AD1 -> 0.025011133 | AE8: =((1+$AI8)^(AE1/365)-1)*365/AE1 -> 0.025024845 | AF8: =((1+$AI8)^(AF1/365)-1)*365/AF1 -> 0.025050581 | AG8: =((1+$AI8)^(AG1/365)-1)*365/AG1 -> 0.025076352 | AH8: 0.025 | AI8: =(1+AH8/365)^365-1 -> 0.025314243 | AK8: Gate I.O | AL8: 0.0376 | AM8: =((1+AR8)^(AM1/365)-1)*365/AM1 -> 0.030816899 | AN8: 0.0548 | AO8: =((1+$AR8)^(AO1/365)-1)*365/AO1 -> 0.030876796 | AP8: =((1+$AR8)^(AP1/365)-1)*365/AP1 -> 0.030915943 | AQ8: 0.0308 | AR8: =(1+AQ8/365)^365-1 -> 0.031277887
C9: =C10*(365/C1) -> 0.03071679 | E9: =E10*(365/E1) -> 0.030776298 | F9: =F10*(365/F1) -> 0.03081519 | L9: =L10*365/L1 -> 0.032618933 | N9: =N10*365/N1 -> 0.032686043 | O9: =O10*365/O1 -> 0.032729909 | U9: =U10*365/U1 -> 0.03111723 | W9: =W10*365/W1 -> 0.031178301 | X9: =X10*365/X1 -> 0.031218215
A10: Gate I.O | B10: 4.00% | C10: =(1+$H10)^(C1/365)-1 -> 0.0011781782 | D10: 5.48% | E10: =(1+$H10)^(E1/365)-1 -> 0.0050591175 | F10: =(1+$H10)^(F1/365)-1 -> 0.0075982661 | G10: =3.07/100 -> 0.0307 | H10: =(1+G10/365)^365-1 -> 0.031174773 | J10: Gate I.O | K10: 3.90% | L10: =(1+Q10)^(L1/365)-1 -> 0.0012511371 | M10: 5.48% | N10: =(1+Q10)^(N1/365)-1 -> 0.0053730481 | O10: =(1+Q10)^(O1/365)-1 -> 0.0080703886 | P10: 0.0326 | Q10: =(1+P10/365)^365-1 -> 0.033135698 | S10: Gate I.O | T10: 0.0386 | U10: =(1+Z10)^(U1/365)-1 -> 0.0011935376 | V10: 0.0548 | W10: =(1+$Z10)^(W1/365)-1 -> 0.0051252001 | X10: =(1+$Z10)^(X1/365)-1 -> 0.0076976422 | Y10: 0.0311 | Z10: =(1+Y10/365)^365-1 -> 0.031587291 | AB10: Gate I.O | AC10: 0.0376 | AD10: =((1+AI10)^(AD1/365)-1)*365/AD1 -> 0.030216247 | AE10: 0.0548 | AF10: =((1+$AI10)^(AF1/365)-1)*365/AF1 -> 0.030273831 | AG10: =((1+$AI10)^(AG1/365)-1)*365/AG1 -> 0.030311464 | AH10: 0.0302 | AI10: =(1+AH10/365)^365-1 -> 0.030659358
A12: 46078 | B12: 7 | C12: 14 | D12: 30 | E12: 60 | F12: 90 | G12: Flexible | H12: Annual | J12: 46088 | K12: 7 | L12: 14 | M12: 30 | N12: 60 | O12: 90 | P12: Flexible | Q12: Annual | S12: 46098 | T12: 7 | U12: 14 | V12: 30 | W12: 60 | X12: 90 | Y12: Flexible | Z12: Annual | AB12: 46108 | AC12: 7 | AD12: 14 | AE12: 30 | AF12: 60 | AG12: 90 | AH12: Flexible | AI12: Annual | AK12: 46118 | AL12: 7 | AM12: 14 | AN12: 30 | AO12: 60 | AP12: 90 | AQ12: Flexible | AR12: Annual
B13: =B14*(365/B12) -> 0.030407597 | C13: =C14*(365/C12) -> 0.030416463 | D13: =D14*(365/D12) -> 0.030436742 | E13: =E14*(365/E12) -> 0.030474813 | F13: =F14*(365/F12) -> 0.030512947 | K13: =K14*365/K12 -> 0.031808313 | L13: =L14*365/L12 -> 0.031818015 | M13: =M14*365/M12 -> 0.031840205 | N13: =N14*365/N12 -> 0.031881868 | O13: =O14*365/O12 -> 0.031923604 | T13: =T14*365/T12 -> 0.033509225 | U13: =U14*365/U12 -> 0.033519993 | V13: =V14*365/V12 -> 0.033544621 | W13: =W14*365/W12 -> 0.033590864 | X13: =X14*365/X12 -> 0.033637191
A14: Binance | B14: =(1+$H14)^(B12/365)-1 -> 0.00058315939 | C14: =(1+$H14)^(C12/365)-1 -> 0.0011666589 | D14: =(1+$H14)^(D12/365)-1 -> 0.00250165 | E14: =(1+$H14)^(E12/365)-1 -> 0.0050095583 | F14: =(1+$H14)^(F12/365)-1 -> 0.0075237404 | G14: 0.0304 | H14: =(1+G14/365)^365-1 -> 0.030865493 | J14: Binance | K14: =(1+$Q14)^(K12/365)-1 -> 0.00061002244 | L14: =(1+$Q14)^(L12/365)-1 -> 0.001220417 | M14: =(1+$Q14)^(M12/365)-1 -> 0.0026170032 | N14: =(1+$Q14)^(N12/365)-1 -> 0.005240855 | O14: =(1+$Q14)^(O12/365)-1 -> 0.0078715735 | P14: 0.0318 | Q14: =(1+P14/365)^365-1 -> 0.032309593 | S14: Binance | T14: =(1+$Z14)^(T12/365)-1 -> 0.00064264268 | U14: =(1+$Z14)^(U12/365)-1 -> 0.0012856983 | V14: =(1+$Z14)^(V12/365)-1 -> 0.0027570921 | W14: =(1+$Z14)^(W12/365)-1 -> 0.0055217858 | X14: =(1+$Z14)^(X12/365)-1 -> 0.008294102 | Y14: 0.0335 | Z14: =(1+Y14/365)^365-1 -> 0.034065854 | AB14: Binance | AC14: =((1+$AI14)^(AC12/365)-1)*365/AC12 -> 0.029907349 | AD14: =((1+$AI14)^(AD12/365)-1)*365/AD12 -> 0.029915926 | AE14: =((1+$AI14)^(AE12/365)-1)*365/AE12 -> 0.029935543 | AF14: =((1+$AI14)^(AF12/365)-1)*365/AF12 -> 0.02997237 | AG14: =((1+$AI14)^(AG12/365)-1)*365/AG12 -> 0.030009258 | AH14: 0.0299 | AI14: =(1+AH14/365)^365-1 -> 0.030350232 | AK14: Binance | AL14: =((1+$AR14)^(AL12/365)-1)*365/AL12 -> 0.0310079 | AM14: =((1+$AR14)^(AM12/365)-1)*365/AM12 -> 0.03101712 | AN14: =((1+$AR14)^(AN12/365)-1)*365/AN12 -> 0.031038207 | AO14: =((1+$AR14)^(AO12/365)-1)*365/AO12 -> 0.031077798 | AP14: =((1+$AR14)^(AP12/365)-1)*365/AP12 -> 0.031117455 | AQ14: 0.031 | AR14: =(1+AQ14/365)^365-1 -> 0.031484146
AK15: Bybit | AL15: 0.031 | AM15: 0.03 | AN15: 0.044 | AO15: 0.057 | AP15: 0.0597 | AQ15: 0.0342 | AR15: =(1+AQ15/365)^365-1 -> 0.034789886
A16: Bybit | B16: 3.00% | C16: 3.15% | D16: 4.39% | E16: 4.99% | F16: 5.85% | G16: 0.0344 | H16: =(1+G16/365)^365-1 -> 0.034996846 | J16: Bybit | K16: 0.0363 | L16: 0.04 | M16: 0.042 | N16: 0.0573 | O16: 0.058 | P16: 0.0356 | Q16: =(1+P16/365)^365-1 -> 0.036239468 | S16: Bybit | T16: 0.03 | U16: 0.0394 | V16: 0.042 | W16: 0.0439 | X16: 0.0507 | Y16: 0.0385 | Z16: =(1+Y16/365)^365-1 -> 0.039248618 | AB16: Bybit | AC16: ='Daily Data'!AT35 -> 0.03 | AD16: ='Daily Data'!AU35 -> 0.033 | AE16: ='Daily Data'!AV35 -> 0.0349 | AF16: ='Daily Data'!AW35 -> 0.044 | AG16: ='Daily Data'!AX35 -> 0.0565 | AH16: 0.0338 | AI16: =(1+AH16/365)^365-1 -> 0.034376092
B17: =B18*365/B12 -> 0.030007398 | C17: =C18*365/C12 -> 0.030016033 | D17: =D18*365/D12 -> 0.030035781 | E17: =E18*365/E12 -> 0.030072855 | F17: =F18*365/F12 -> 0.030109991 | K17: =K18*365/K12 -> 0.025005138 | L17: =L18*365/L12 -> 0.025011133 | M17: =M18*365/M12 -> 0.025024845 | N17: =N18*365/N12 -> 0.025050581 | O17: =O18*365/O12 -> 0.025076352 | T17: =(T18*365/T12) -> 0.025005138 | U17: =(U18*365/U12) -> 0.025011133 | V17: =(V18*365/V12) -> 0.025024845 | W17: =(W18*365/W12) -> 0.025050581 | X17: =(X18*365/X12) -> 0.025076352 | AK17: OKX | AL17: =((1+$AR17)^(AL12/365)-1)*365/AL12 -> 0.025005138 | AM17: =((1+$AR17)^(AM12/365)-1)*365/AM12 -> 0.025011133 | AN17: =((1+$AR17)^(AN12/365)-1)*365/AN12 -> 0.025024845 | AO17: =((1+$AR17)^(AO12/365)-1)*365/AO12 -> 0.025050581 | AP17: =((1+$AR17)^(AP12/365)-1)*365/AP12 -> 0.025076352 | AQ17: 0.025 | AR17: =(1+AQ17/365)^365-1 -> 0.025314243
A18: OKX | B18: =(1+$H18)^(B12/365)-1 -> 0.00057548435 | C18: =(1+$H18)^(C12/365)-1 -> 0.0011512999 | D18: =(1+$H18)^(D12/365)-1 -> 0.0024686943 | E18: =(1+$H18)^(E12/365)-1 -> 0.0049434831 | F18: =(1+$H18)^(F12/365)-1 -> 0.0074243814 | G18: 0.03 | H18: =(1+G18/365)^365-1 -> 0.030453264 | J18: OKX | K18: =(1+$Q18)^(K12/365)-1 -> 0.00047955058 | L18: =(1+$Q18)^(L12/365)-1 -> 0.00095933114 | M18: =(1+$Q18)^(M12/365)-1 -> 0.0020568365 | N18: =(1+$Q18)^(N12/365)-1 -> 0.0041179037 | O18: =(1+$Q18)^(O12/365)-1 -> 0.0061832101 | P18: 0.025 | Q18: =(1+P18/365)^365-1 -> 0.025314243 | S18: OKX | T18: =(1+$Z18)^(T12/365)-1 -> 0.00047955058 | U18: =(1+$Z18)^(U12/365)-1 -> 0.00095933114 | V18: =(1+$Z18)^(V12/365)-1 -> 0.0020568365 | W18: =(1+$Z18)^(W12/365)-1 -> 0.0041179037 | X18: =(1+$Z18)^(X12/365)-1 -> 0.0061832101 | Y18: 0.025 | Z18: =(1+Y18/365)^365-1 -> 0.025314243 | AB18: OKX | AC18: =((1+$AI18)^(AC12/365)-1)*365/AC12 -> 0.025005138 | AD18: =((1+$AI18)^(AD12/365)-1)*365/AD12 -> 0.025011133 | AE18: =((1+$AI18)^(AE12/365)-1)*365/AE12 -> 0.025024845 | AF18: =((1+$AI18)^(AF12/365)-1)*365/AF12 -> 0.025050581 | AG18: =((1+$AI18)^(AG12/365)-1)*365/AG12 -> 0.025076352 | AH18: 0.025 | AI18: =(1+AH18/365)^365-1 -> 0.025314243
C19: =C20*365/C12 -> 0.03071679 | E19: =E20*365/E12 -> 0.030776298 | F19: =F20*365/90 -> 0.03081519 | L19: =L20*365/L12 -> 0.032318586 | N19: =N20*365/N12 -> 0.032384465 | O19: =O20*365/O12 -> 0.032427526 | U19: =U20*365/U12 -> 0.03111723 | W19: =W20*365/W12 -> 0.031178301 | X19: =X20*365/X12 -> 0.031218215 | AK19: Gate I.O | AL19: 0.0376 | AM19: =((1+AR19)^(AM12/365)-1)*365/AM12 -> 0.030816899 | AN19: 0.0548 | AO19: =((1+$AR19)^(AO12/365)-1)*365/AO12 -> 0.030876796 | AP19: =((1+$AR19)^(AP12/365)-1)*365/AP12 -> 0.030915943 | AQ19: 0.0308 | AR19: =(1+AQ19/365)^365-1 -> 0.031277887
A20: Gate I.O | B20: 4.00% | C20: =(1+$H20)^(C12/365)-1 -> 0.0011781782 | D20: 5.48% | E20: =(1+$H20)^(E12/365)-1 -> 0.0050591175 | F20: =(1+$H20)^(F12/365)-1 -> 0.0075982661 | G20: 0.0307 | H20: =(1+G20/365)^365-1 -> 0.031174773 | J20: Gate I.O | K20: 3.86% | L20: =(1+Q20)^(L12/365)-1 -> 0.001239617 | M20: 5.48% | N20: =(1+Q20)^(N12/365)-1 -> 0.0053234737 | O20: =(1+Q20)^(90/365)-1 -> 0.0079958284 | P20: 0.0323 | Q20: =(1+P20/365)^365-1 -> 0.032825831 | S20: Gate I.O | T20: 0.0386 | U20: =(1+Z20)^(U12/365)-1 -> 0.0011935376 | V20: 0.0548 | W20: =(1+Z20)^(W12/365)-1 -> 0.0051252001 | X20: =(1+Z20)^(X12/365)-1 -> 0.0076976422 | Y20: 0.0311 | Z20: =(1+Y20/365)^365-1 -> 0.031587291 | AB20: Gate I.O | AC20: 0.0376 | AD20: =((1+AI20)^(AD12/365)-1)*365/AD12 -> 0.030216247 | AE20: 0.0548 | AF20: =((1+$AI20)^(AF12/365)-1)*365/AF12 -> 0.030273831 | AG20: =((1+$AI20)^(AG12/365)-1)*365/AG12 -> 0.030311464 | AH20: 0.0302 | AI20: =(1+AH20/365)^365-1 -> 0.030659358
A22: 46079 | B22: 7 | C22: 14 | D22: 30 | E22: 60 | F22: 90 | G22: Flexible | H22: Annual | J22: 46089 | K22: 7 | L22: 14 | M22: 30 | N22: 60 | O22: 90 | P22: Flexible | Q22: Annual | S22: 46099 | T22: 7 | U22: 14 | V22: 30 | W22: 60 | X22: 90 | Y22: Flexible | Z22: Annual | AB22: 46109 | AC22: 7 | AD22: 14 | AE22: 30 | AF22: 60 | AG22: 90 | AH22: Flexible | AI22: Annual | AK22: 46119 | AL22: 7 | AM22: 14 | AN22: 30 | AO22: 60 | AP22: 90 | AQ22: Flexible | AR22: Annual
B23: =B24*(365/B22) -> 0.031908365 | C23: =C24*(365/C22) -> 0.031918128 | D23: =D24*(365/D22) -> 0.031940459 | E23: =E24*(365/E22) -> 0.031982384 | F23: =F24*(365/F22) -> 0.032024383 | K23: =K24*365/K22 -> 0.030707748 | L23: =L24*365/L22 -> 0.03071679 | M23: =M24*365/M22 -> 0.030737471 | N23: =N24*365/N22 -> 0.030776298 | O23: =O24*365/O22 -> 0.03081519 | T23: =T24*365/T22 -> 0.032308576 | U23: =U24*365/U22 -> 0.032318586 | V23: =V24*365/V22 -> 0.03234148 | W23: =W24*365/W22 -> 0.032384465 | X23: =X24*365/X22 -> 0.032427526
A24: Binance | B24: =(1+$H24)^(B22/365)-1 -> 0.00061194125 | C24: =(1+$H24)^(C22/365)-1 -> 0.001224257 | D24: =(1+$H24)^(D22/365)-1 -> 0.0026252432 | E24: =(1+$H24)^(E22/365)-1 -> 0.0052573782 | F24: =(1+$H24)^(F22/365)-1 -> 0.0078964233 | G24: 0.0319 | H24: =(1+G24/365)^365-1 -> 0.03241282 | J24: Binance | K24: =(1+$Q24)^(K22/365)-1 -> 0.00058891571 | L24: =(1+$Q24)^(L22/365)-1 -> 0.0011781782 | M24: =(1+$Q24)^(M22/365)-1 -> 0.0025263675 | N24: =(1+$Q24)^(N22/365)-1 -> 0.0050591175 | O24: =(1+$Q24)^(O22/365)-1 -> 0.0075982661 | P24: 0.0307 | Q24: =(1+P24/365)^365-1 -> 0.031174773 | S24: Binance | T24: =(1+$Z24)^(T22/365)-1 -> 0.00061961653 | U24: =(1+$Z24)^(U22/365)-1 -> 0.001239617 | V24: =(1+$Z24)^(V22/365)-1 -> 0.0026582038 | W24: =(1+$Z24)^(W22/365)-1 -> 0.0053234737 | X24: =(1+$Z24)^(X22/365)-1 -> 0.0079958284 | Y24: 0.0323 | Z24: =(1+Y24/365)^365-1 -> 0.032825831 | AB24: Binance | AC24: =((1+$AI24)^(AC22/365)-1)*365/AC22 -> 0.0298073 | AD24: =((1+$AI24)^(AD22/365)-1)*365/AD22 -> 0.02981582 | AE24: =((1+$AI24)^(AE22/365)-1)*365/AE22 -> 0.029835305 | AF24: =((1+$AI24)^(AF22/365)-1)*365/AF22 -> 0.029871887 | AG24: =((1+$AI24)^(AG22/365)-1)*365/AG22 -> 0.029908528 | AH24: 0.0298 | AI24: =(1+AH24/365)^365-1 -> 0.03024721 | AK24: Binance | AL24: =((1+$AR24)^(AL22/365)-1)*365/AL22 -> 0.031208002 | AM24: =((1+$AR24)^(AM22/365)-1)*365/AM22 -> 0.031217341 | AN24: =((1+$AR24)^(AN22/365)-1)*365/AN22 -> 0.031238702 | AO24: =((1+$AR24)^(AO22/365)-1)*365/AO22 -> 0.031278805 | AP24: =((1+$AR24)^(AP22/365)-1)*365/AP22 -> 0.031318978 | AQ24: 0.0312 | AR24: =(1+AQ24/365)^365-1 -> 0.031690446
AK25: Bybit | AL25: 0.0339 | AM25: 0.034 | AN25: 0.0439 | AO25: 0.04 | AP25: 0.05 | AQ25: 0.0353 | AR25: =(1+AQ25/365)^365-1 -> 0.035928673
A26: Bybit | B26: 0.033 | C26: 0.034 | D26: 0.043 | E26: 0.05 | F26: 0.0585 | G26: 0.035 | H26: =(1+G26/365)^365-1 -> 0.035617971 | J26: Bybit | K26: 0.0375 | L26: 0.0409 | M26: 0.042 | N26: 0.0573 | O26: 0.058 | P26: 0.0354 | Q26: =(1+P26/365)^365-1 -> 0.036032261 | S26: Bybit | T26: ='Daily Data'!AT26 -> 0.035 | U26: ='Daily Data'!AU26 -> 0.042 | V26: ='Daily Data'!AV26 -> 0.04 | W26: ='Daily Data'!AW26 -> 0.042 | X26: ='Daily Data'!AX26 -> 0.0505 | Y26: 0.0357 | Z26: =(1+Y26/365)^365-1 -> 0.036343087 | AB26: Bybit | AC26: ='Daily Data'!AT36 -> 0.03 | AD26: ='Daily Data'!AU36 -> 0.033 | AE26: ='Daily Data'!AV36 -> 0.026 | AF26: ='Daily Data'!AW36 -> 0.044 | AG26: ='Daily Data'!AX36 -> 0.0261 | AH26: 0.0339 | AI26: =(1+AH26/365)^365-1 -> 0.034479525
B27: =B28*365/B22 -> 0.025005138 | C27: =C28*365/C22 -> 0.025011133 | D27: =D28*365/D22 -> 0.025024845 | E27: =E28*365/E22 -> 0.025050581 | F27: =F28*365/F22 -> 0.025076352 | K27: =K28*365/K22 -> 0.025005138 | L27: =L28*365/L22 -> 0.025011133 | M27: =M28*365/M22 -> 0.025024845 | N27: =N28*365/N22 -> 0.025050581 | O27: =O28*365/O22 -> 0.025076352 | T27: =T28*365/T22 -> 0.025005138 | U27: =U28*365/U22 -> 0.025011133 | V27: =V28*365/V22 -> 0.025024845 | W27: =W28*365/W22 -> 0.025050581 | X27: =X28*365/X22 -> 0.025076352 | AK27: OKX | AL27: =((1+$AR27)^(AL22/365)-1)*365/AL22 -> 0.025005138 | AM27: =((1+$AR27)^(AM22/365)-1)*365/AM22 -> 0.025011133 | AN27: =((1+$AR27)^(AN22/365)-1)*365/AN22 -> 0.025024845 | AO27: =((1+$AR27)^(AO22/365)-1)*365/AO22 -> 0.025050581 | AP27: =((1+$AR27)^(AP22/365)-1)*365/AP22 -> 0.025076352 | AQ27: 0.025 | AR27: =(1+AQ27/365)^365-1 -> 0.025314243
A28: OKX | B28: =(1+$H28)^(B22/365)-1 -> 0.00047955058 | C28: =(1+$H28)^(C22/365)-1 -> 0.00095933114 | D28: =(1+$H28)^(D22/365)-1 -> 0.0020568365 | E28: =(1+$H28)^(E22/365)-1 -> 0.0041179037 | F28: =(1+$H28)^(F22/365)-1 -> 0.0061832101 | G28: 0.025 | H28: =(1+G28/365)^365-1 -> 0.025314243 | J28: OKX | K28: =(1+$Q28)^(K22/365)-1 -> 0.00047955058 | L28: =(1+$Q28)^(L22/365)-1 -> 0.00095933114 | M28: =(1+$Q28)^(M22/365)-1 -> 0.0020568365 | N28: =(1+$Q28)^(N22/365)-1 -> 0.0041179037 | O28: =(1+$Q28)^(O22/365)-1 -> 0.0061832101 | P28: 0.025 | Q28: =(1+P28/365)^365-1 -> 0.025314243 | S28: OKX | T28: =(1+$Z28)^(T22/365)-1 -> 0.00047955058 | U28: =(1+$Z28)^(U22/365)-1 -> 0.00095933114 | V28: =(1+$Z28)^(V22/365)-1 -> 0.0020568365 | W28: =(1+$Z28)^(W22/365)-1 -> 0.0041179037 | X28: =(1+$Z28)^(X22/365)-1 -> 0.0061832101 | Y28: 0.025 | Z28: =(1+Y28/365)^365-1 -> 0.025314243 | AB28: OKX | AC28: =((1+$AI28)^(AC22/365)-1)*365/AC22 -> 0.025005138 | AD28: =((1+$AI28)^(AD22/365)-1)*365/AD22 -> 0.025011133 | AE28: =((1+$AI28)^(AE22/365)-1)*365/AE22 -> 0.025024845 | AF28: =((1+$AI28)^(AF22/365)-1)*365/AF22 -> 0.025050581 | AG28: =((1+$AI28)^(AG22/365)-1)*365/AG22 -> 0.025076352 | AH28: 0.025 | AI28: =(1+AH28/365)^365-1 -> 0.025314243
C29: =C30*(365/C22) -> 0.03071679 | E29: =E30*(365/E22) -> 0.030776298 | F29: =F30*(365/90) -> 0.03081519 | L29: =L30*365/L22 -> 0.032318586 | N29: =N30*365/N22 -> 0.032384465 | O29: =O30*365/O22 -> 0.032427526 | U29: =U30*365/U22 -> 0.031217341 | W29: =W30*365/W22 -> 0.031278805 | X29: =X30*365/X22 -> 0.031318978 | AK29: Gate I.O | AL29: 0.0386 | AM29: =((1+AR29)^(AM22/365)-1)*365/AM22 -> 0.032218471 | AN29: 0.0548 | AO29: =((1+$AR29)^(AO22/365)-1)*365/AO22 -> 0.032283943 | AP29: =((1+$AR29)^(AP22/365)-1)*365/AP22 -> 0.032326737 | AQ29: 0.0322 | AR29: =(1+AQ29/365)^365-1 -> 0.032722563
A30: Gate I.O | B30: 0.0398 | C30: =(1+$H30)^(C22/365)-1 -> 0.0011781782 | D30: 0.0548 | E30: =(1+H30)^(E22/365)-1 -> 0.0050591175 | F30: =(1+H30)^(F22/365)-1 -> 0.0075982661 | G30: 0.0307 | H30: =(1+G30/365)^365-1 -> 0.031174773 | J30: Gate I.O | K30: 3.86% | L30: =(1+Q30)^(L22/365)-1 -> 0.001239617 | M30: 5.48% | N30: =(1+Q30)^(N22/365)-1 -> 0.0053234737 | O30: =(1+Q30)^(O22/365)-1 -> 0.0079958284 | P30: 0.0323 | Q30: =(1+P30/365)^365-1 -> 0.032825831 | S30: Gate I.O | T30: 0.0376 | U30: =(1+Z30)^(U22/365)-1 -> 0.0011973775 | V30: 0.0548 | W30: =(1+Z30)^(W22/365)-1 -> 0.0051417214 | X30: =(1+Z30)^(X22/365)-1 -> 0.0077224877 | Y30: 0.0312 | Z30: =(1+Y30/365)^365-1 -> 0.031690446 | AB30: Gate I.O | AC30: 0.0386 | AD30: =((1+AI30)^(AD22/365)-1)*365/AD22 -> 0.02981582 | AE30: 0.0548 | AF30: =((1+$AI30)^(AF22/365)-1)*365/AF22 -> 0.029871887 | AG30: =((1+$AI30)^(AG22/365)-1)*365/AG22 -> 0.029908528 | AH30: 0.0298 | AI30: =(1+AH30/365)^365-1 -> 0.03024721
A32: 46080 | B32: 7 | C32: 14 | D32: 30 | E32: 60 | F32: 90 | G32: Flexible | H32: Annual | J32: 46090 | K32: 7 | L32: 14 | M32: 30 | N32: 60 | O32: 90 | P32: Flexible | Q32: Annual | S32: 46100 | T32: 7 | U32: 14 | V32: 30 | W32: 60 | X32: 90 | Y32: Flexible | Z32: Annual | AB32: 46110 | AC32: 7 | AD32: 14 | AE32: 30 | AF32: 60 | AG32: 90 | AH32: Flexible | AI32: Annual | AK32: 46120 | AL32: 7 | AM32: 14 | AN32: 30 | AO32: 60 | AP32: 90 | AQ32: Flexible | AR32: Annual
B33: =B34*(365/B32) -> 0.032208523 | C33: =C34*(365/C32) -> 0.032218471 | D33: =D34*(365/D32) -> 0.032241223 | E33: =E34*(365/E32) -> 0.032283943 | F33: =F34*(365/F32) -> 0.032326737 | K33: =K34*365/K32 -> 0.0310079 | L33: =L34*365/L32 -> 0.03101712 | M33: =M34*365/M32 -> 0.031038207 | N33: =N34*365/N32 -> 0.031077798 | O33: =O34*365/O32 -> 0.031117455 | T33: =T34*365/T32 -> 0.030507647 | U33: =U34*365/U32 -> 0.030516572 | V33: =V34*365/V32 -> 0.030536984 | W33: =W34*365/W32 -> 0.030575306 | X33: =X34*365/X32 -> 0.030613693
A34: Binance | B34: =(1+$H34)^(B32/365)-1 -> 0.00061769771 | C34: =(1+$H34)^(C32/365)-1 -> 0.001235777 | D34: =(1+$H34)^(D32/365)-1 -> 0.0026499636 | E34: =(1+$H34)^(E32/365)-1 -> 0.0053069495 | F34: =(1+$H34)^(F32/365)-1 -> 0.0079709762 | G34: 0.0322 | H34: =(1+G34/365)^365-1 -> 0.032722563 | J34: Binance | K34: =(1+$Q34)^(K32/365)-1 -> 0.00059467205 | L34: =(1+$Q34)^(L32/365)-1 -> 0.0011896977 | M34: =(1+$Q34)^(M32/365)-1 -> 0.0025510855 | N34: =(1+$Q34)^(N32/365)-1 -> 0.005108679 | O34: =(1+$Q34)^(O32/365)-1 -> 0.0076727972 | P34: 0.031 | Q34: =(1+P34/365)^365-1 -> 0.031484146 | S34: Binance | T34: =(1+$Z34)^(T32/365)-1 -> 0.00058507816 | U34: =(1+$Z34)^(U32/365)-1 -> 0.0011704986 | V34: =(1+$Z34)^(V32/365)-1 -> 0.0025098891 | W34: =(1+$Z34)^(W32/365)-1 -> 0.0050260777 | X34: =(1+$Z34)^(X32/365)-1 -> 0.0075485817 | Y34: 0.0305 | Z34: =(1+Y34/365)^365-1 -> 0.030968576 | AB34: Binance | AC34: =((1+$AI34)^(AC32/365)-1)*365/AC32 -> 0.029907349 | AD34: =((1+$AI34)^(AD32/365)-1)*365/AD32 -> 0.029915926 | AE34: =((1+$AI34)^(AE32/365)-1)*365/AE32 -> 0.029935543 | AF34: =((1+$AI34)^(AF32/365)-1)*365/AF32 -> 0.02997237 | AG34: =((1+$AI34)^(AG32/365)-1)*365/AG32 -> 0.030009258 | AH34: 0.0299 | AI34: =(1+AH34/365)^365-1 -> 0.030350232 | AK34: Binance | AL34: =((1+$AR34)^(AL32/365)-1)*365/AL32 -> 0.033609281 | AM34: =((1+$AR34)^(AM32/365)-1)*365/AM32 -> 0.033620112 | AN34: =((1+$AR34)^(AN32/365)-1)*365/AN32 -> 0.033644888 | AO34: =((1+$AR34)^(AO32/365)-1)*365/AO32 -> 0.033691407 | AP34: =((1+$AR34)^(AP32/365)-1)*365/AP32 -> 0.033738013 | AQ34: 0.0336 | AR34: =(1+AQ34/365)^365-1 -> 0.034169256
AK35: Bybit | AL35: 0.0339 | AM35: 0.0349 | AN35: 0.0439 | AO35: 0.044 | AP35: 0.065 | AQ35: 0.0368 | AR35: =(1+AQ35/365)^365-1 -> 0.037483578
A36: Bybit | B36: 0.03 | C36: 0.034 | D36: 0.0434 | E36: 0.05 | F36: 0.0547 | G36: 0.0354 | H36: =(1+G36/365)^365-1 -> 0.036032261 | J36: Bybit | K36: 0.032 | L36: 0.0409 | M36: 0.038 | N36: 0.05 | O36: 0.0524 | P36: 0.0344 | Q36: =(1+P36/365)^365-1 -> 0.034996846 | S36: Bybit | T36: ='Daily Data'!AT27 -> 0.0342 | U36: ='Daily Data'!AU27 -> 0.042 | V36: ='Daily Data'!AV27 -> 0.035 | W36: ='Daily Data'!AW27 -> 0.044 | X36: ='Daily Data'!AX27 -> 0.0507 | Y36: 0.0343 | Z36: =(1+Y36/365)^365-1 -> 0.034893361 | AB36: Bybit | AC36: 0.03 | AD36: 0.033 | AE36: 0.032 | AF36: 0.044 | AG36: 0.056 | AH36: 0.033 | AI36: =(1+AH36/365)^365-1 -> 0.033548998
B37: =B38*(365/B32) -> 0.025005138 | C37: =C38*(365/C32) -> 0.025011133 | D37: =D38*(365/D32) -> 0.025024845 | E37: =E38*(365/E32) -> 0.025050581 | F37: =F38*(365/F32) -> 0.025076352 | K37: =K38*365/K32 -> 0.025005138 | L37: =L38*365/L32 -> 0.025011133 | M37: =M38*365/M32 -> 0.025024845 | N37: =N38*365/N32 -> 0.025050581 | O37: =O38*365/O32 -> 0.025076352 | AK37: OKX | AL37: =((1+$AR37)^(AL32/365)-1)*365/AL32 -> 0.025005138 | AM37: =((1+$AR37)^(AM32/365)-1)*365/AM32 -> 0.025011133 | AN37: =((1+$AR37)^(AN32/365)-1)*365/AN32 -> 0.025024845 | AO37: =((1+$AR37)^(AO32/365)-1)*365/AO32 -> 0.025050581 | AP37: =((1+$AR37)^(AP32/365)-1)*365/AP32 -> 0.025076352 | AQ37: 0.025 | AR37: =(1+AQ37/365)^365-1 -> 0.025314243
A38: OKX | B38: =(1+$H38)^(B32/365)-1 -> 0.00047955058 | C38: =(1+$H38)^(C32/365)-1 -> 0.00095933114 | D38: =(1+$H38)^(D32/365)-1 -> 0.0020568365 | E38: =(1+$H38)^(E32/365)-1 -> 0.0041179037 | F38: =(1+$H38)^(F32/365)-1 -> 0.0061832101 | G38: 0.025 | H38: =(1+G38/365)^365-1 -> 0.025314243 | J38: OKX | K38: =(1+$Q38)^(K32/365)-1 -> 0.00047955058 | L38: =(1+$Q38)^(L32/365)-1 -> 0.00095933114 | M38: =(1+$Q38)^(M32/365)-1 -> 0.0020568365 | N38: =(1+$Q38)^(N32/365)-1 -> 0.0041179037 | O38: =(1+$Q38)^(O32/365)-1 -> 0.0061832101 | P38: 0.025 | Q38: =(1+P38/365)^365-1 -> 0.025314243 | S38: OKX | T38: =((1+$Z38)^(T32/365)-1)*365/T32 -> 0.025005138 | U38: =((1+$Z38)^(U32/365)-1)*365/U32 -> 0.025011133 | V38: =((1+$Z38)^(V32/365)-1)*365/V32 -> 0.025024845 | W38: =((1+$Z38)^(W32/365)-1)*365/W32 -> 0.025050581 | X38: =((1+$Z38)^(X32/365)-1)*365/X32 -> 0.025076352 | Y38: 0.025 | Z38: =(1+Y38/365)^365-1 -> 0.025314243 | AB38: OKX | AC38: =((1+$AI38)^(AC32/365)-1)*365/AC32 -> 0.025005138 | AD38: =((1+$AI38)^(AD32/365)-1)*365/AD32 -> 0.025011133 | AE38: =((1+$AI38)^(AE32/365)-1)*365/AE32 -> 0.025024845 | AF38: =((1+$AI38)^(AF32/365)-1)*365/AF32 -> 0.025050581 | AG38: =((1+$AI38)^(AG32/365)-1)*365/AG32 -> 0.025076352 | AH38: 0.025 | AI38: =(1+AH38/365)^365-1 -> 0.025314243
C39: =C40*365/C32 -> 0.030416463 | E39: =E40*365/E32 -> 0.030474813 | F39: =F40*365/F32 -> 0.030512947 | L39: =L40*365/L32 -> 0.031417564 | N39: =N40*365/N32 -> 0.03147982 | O39: =O40*365/O32 -> 0.03152051 | AK39: Gate I.O | AL39: 0.0402 | AM39: =((1+AR39)^(AM32/365)-1)*365/AM32 -> 0.033620112 | AN39: 0.0548 | AO39: =((1+$AR39)^(AO32/365)-1)*365/AO32 -> 0.033691407 | AP39: =((1+$AR39)^(AP32/365)-1)*365/AP32 -> 0.033738013 | AQ39: 0.0336 | AR39: =(1+AQ39/365)^365-1 -> 0.034169256
